[2023-03-29T07:06:53.013+0000] {taskinstance.py:1087} INFO - Dependencies all met for <TaskInstance: docker_dag.docker_command scheduled__2023-03-29T05:05:00+00:00 [queued]>
[2023-03-29T07:06:53.022+0000] {taskinstance.py:1087} INFO - Dependencies all met for <TaskInstance: docker_dag.docker_command scheduled__2023-03-29T05:05:00+00:00 [queued]>
[2023-03-29T07:06:53.022+0000] {taskinstance.py:1283} INFO - 
--------------------------------------------------------------------------------
[2023-03-29T07:06:53.022+0000] {taskinstance.py:1284} INFO - Starting attempt 2 of 2
[2023-03-29T07:06:53.022+0000] {taskinstance.py:1285} INFO - 
--------------------------------------------------------------------------------
[2023-03-29T07:06:53.289+0000] {taskinstance.py:1304} INFO - Executing <Task(DockerOperator): docker_command> on 2023-03-29 05:05:00+00:00
[2023-03-29T07:06:53.294+0000] {standard_task_runner.py:55} INFO - Started process 370858 to run task
[2023-03-29T07:06:53.299+0000] {standard_task_runner.py:82} INFO - Running: ['airflow', 'tasks', 'run', 'docker_dag', 'docker_command', 'scheduled__2023-03-29T05:05:00+00:00', '--job-id', '540', '--raw', '--subdir', 'DAGS_FOLDER/test_docker_dag.py', '--cfg-path', '/tmp/tmpo14q95ay']
[2023-03-29T07:06:53.301+0000] {standard_task_runner.py:83} INFO - Job 540: Subtask docker_command
[2023-03-29T07:06:53.369+0000] {task_command.py:389} INFO - Running <TaskInstance: docker_dag.docker_command scheduled__2023-03-29T05:05:00+00:00 [running]> on host vibrdairflow.tciw5gv3lhjetcyg0kqzfvdylc.hx.internal.cloudapp.net
[2023-03-29T07:06:53.433+0000] {taskinstance.py:1511} INFO - Exporting the following env vars:
AIRFLOW_CTX_DAG_OWNER=airflow
AIRFLOW_CTX_DAG_ID=docker_dag
AIRFLOW_CTX_TASK_ID=docker_command
AIRFLOW_CTX_EXECUTION_DATE=2023-03-29T05:05:00+00:00
AIRFLOW_CTX_TRY_NUMBER=2
AIRFLOW_CTX_DAG_RUN_ID=scheduled__2023-03-29T05:05:00+00:00
[2023-03-29T07:06:53.439+0000] {taskinstance.py:1772} ERROR - Task failed with exception
Traceback (most recent call last):
  File "/home/azureuser/.local/lib/python3.8/site-packages/urllib3/connectionpool.py", line 703, in urlopen
    httplib_response = self._make_request(
  File "/home/azureuser/.local/lib/python3.8/site-packages/urllib3/connectionpool.py", line 398, in _make_request
    conn.request(method, url, **httplib_request_kw)
  File "/usr/lib/python3.8/http/client.py", line 1256, in request
    self._send_request(method, url, body, headers, encode_chunked)
  File "/usr/lib/python3.8/http/client.py", line 1302, in _send_request
    self.endheaders(body, encode_chunked=encode_chunked)
  File "/usr/lib/python3.8/http/client.py", line 1251, in endheaders
    self._send_output(message_body, encode_chunked=encode_chunked)
  File "/usr/lib/python3.8/http/client.py", line 1011, in _send_output
    self.send(msg)
  File "/usr/lib/python3.8/http/client.py", line 951, in send
    self.connect()
  File "/home/azureuser/.local/lib/python3.8/site-packages/docker/transport/unixconn.py", line 30, in connect
    sock.connect(self.unix_socket)
PermissionError: [Errno 13] Permission denied

During handling of the above exception, another exception occurred:

Traceback (most recent call last):
  File "/home/azureuser/.local/lib/python3.8/site-packages/requests/adapters.py", line 489, in send
    resp = conn.urlopen(
  File "/home/azureuser/.local/lib/python3.8/site-packages/urllib3/connectionpool.py", line 787, in urlopen
    retries = retries.increment(
  File "/home/azureuser/.local/lib/python3.8/site-packages/urllib3/util/retry.py", line 550, in increment
    raise six.reraise(type(error), error, _stacktrace)
  File "/home/azureuser/.local/lib/python3.8/site-packages/urllib3/packages/six.py", line 769, in reraise
    raise value.with_traceback(tb)
  File "/home/azureuser/.local/lib/python3.8/site-packages/urllib3/connectionpool.py", line 703, in urlopen
    httplib_response = self._make_request(
  File "/home/azureuser/.local/lib/python3.8/site-packages/urllib3/connectionpool.py", line 398, in _make_request
    conn.request(method, url, **httplib_request_kw)
  File "/usr/lib/python3.8/http/client.py", line 1256, in request
    self._send_request(method, url, body, headers, encode_chunked)
  File "/usr/lib/python3.8/http/client.py", line 1302, in _send_request
    self.endheaders(body, encode_chunked=encode_chunked)
  File "/usr/lib/python3.8/http/client.py", line 1251, in endheaders
    self._send_output(message_body, encode_chunked=encode_chunked)
  File "/usr/lib/python3.8/http/client.py", line 1011, in _send_output
    self.send(msg)
  File "/usr/lib/python3.8/http/client.py", line 951, in send
    self.connect()
  File "/home/azureuser/.local/lib/python3.8/site-packages/docker/transport/unixconn.py", line 30, in connect
    sock.connect(self.unix_socket)
urllib3.exceptions.ProtocolError: ('Connection aborted.', PermissionError(13, 'Permission denied'))

During handling of the above exception, another exception occurred:

Traceback (most recent call last):
  File "/home/azureuser/.local/lib/python3.8/site-packages/docker/api/client.py", line 214, in _retrieve_server_version
    return self.version(api_version=False)["ApiVersion"]
  File "/home/azureuser/.local/lib/python3.8/site-packages/docker/api/daemon.py", line 181, in version
    return self._result(self._get(url), json=True)
  File "/home/azureuser/.local/lib/python3.8/site-packages/docker/utils/decorators.py", line 46, in inner
    return f(self, *args, **kwargs)
  File "/home/azureuser/.local/lib/python3.8/site-packages/docker/api/client.py", line 237, in _get
    return self.get(url, **self._set_request_timeout(kwargs))
  File "/home/azureuser/.local/lib/python3.8/site-packages/requests/sessions.py", line 600, in get
    return self.request("GET", url, **kwargs)
  File "/home/azureuser/.local/lib/python3.8/site-packages/requests/sessions.py", line 587, in request
    resp = self.send(prep, **send_kwargs)
  File "/home/azureuser/.local/lib/python3.8/site-packages/requests/sessions.py", line 701, in send
    r = adapter.send(request, **kwargs)
  File "/home/azureuser/.local/lib/python3.8/site-packages/requests/adapters.py", line 547, in send
    raise ConnectionError(err, request=request)
requests.exceptions.ConnectionError: ('Connection aborted.', PermissionError(13, 'Permission denied'))

During handling of the above exception, another exception occurred:

Traceback (most recent call last):
  File "/home/azureuser/.local/lib/python3.8/site-packages/airflow/providers/docker/operators/docker.py", line 431, in execute
    if self.force_pull or not self.cli.images(name=self.image):
  File "/home/azureuser/.local/lib/python3.8/site-packages/airflow/providers/docker/operators/docker.py", line 302, in cli
    return self.hook.api_client
  File "/usr/lib/python3.8/functools.py", line 967, in __get__
    val = self.func(instance)
  File "/home/azureuser/.local/lib/python3.8/site-packages/airflow/providers/docker/hooks/docker.py", line 118, in api_client
    client = APIClient(
  File "/home/azureuser/.local/lib/python3.8/site-packages/docker/api/client.py", line 197, in __init__
    self._version = self._retrieve_server_version()
  File "/home/azureuser/.local/lib/python3.8/site-packages/docker/api/client.py", line 221, in _retrieve_server_version
    raise DockerException(
docker.errors.DockerException: Error while fetching server API version: ('Connection aborted.', PermissionError(13, 'Permission denied'))
[2023-03-29T07:06:53.445+0000] {taskinstance.py:1322} INFO - Marking task as FAILED. dag_id=docker_dag, task_id=docker_command, execution_date=20230329T050500, start_date=20230329T070653, end_date=20230329T070653
[2023-03-29T07:06:53.469+0000] {standard_task_runner.py:100} ERROR - Failed to execute job 540 for task docker_command (Error while fetching server API version: ('Connection aborted.', PermissionError(13, 'Permission denied')); 370858)
[2023-03-29T07:06:53.512+0000] {local_task_job.py:159} INFO - Task exited with return code 1
[2023-03-29T07:06:53.532+0000] {taskinstance.py:2582} INFO - 0 downstream tasks scheduled from follow-on schedule check
