[2023-03-29T04:37:31.179+0000] {taskinstance.py:1087} INFO - Dependencies all met for <TaskInstance: docker_sample.docker_op_tester scheduled__2023-03-27T01:40:00+00:00 [queued]>
[2023-03-29T04:37:31.186+0000] {taskinstance.py:1087} INFO - Dependencies all met for <TaskInstance: docker_sample.docker_op_tester scheduled__2023-03-27T01:40:00+00:00 [queued]>
[2023-03-29T04:37:31.186+0000] {taskinstance.py:1283} INFO - 
--------------------------------------------------------------------------------
[2023-03-29T04:37:31.186+0000] {taskinstance.py:1284} INFO - Starting attempt 1 of 2
[2023-03-29T04:37:31.186+0000] {taskinstance.py:1285} INFO - 
--------------------------------------------------------------------------------
[2023-03-29T04:37:31.208+0000] {taskinstance.py:1304} INFO - Executing <Task(DockerOperator): docker_op_tester> on 2023-03-27 01:40:00+00:00
[2023-03-29T04:37:31.213+0000] {standard_task_runner.py:55} INFO - Started process 180084 to run task
[2023-03-29T04:37:31.219+0000] {standard_task_runner.py:82} INFO - Running: ['airflow', 'tasks', 'run', 'docker_sample', 'docker_op_tester', 'scheduled__2023-03-27T01:40:00+00:00', '--job-id', '121', '--raw', '--subdir', 'DAGS_FOLDER/test_docker_operator.py', '--cfg-path', '/tmp/tmpwl3963et']
[2023-03-29T04:37:31.220+0000] {standard_task_runner.py:83} INFO - Job 121: Subtask docker_op_tester
[2023-03-29T04:37:31.283+0000] {task_command.py:389} INFO - Running <TaskInstance: docker_sample.docker_op_tester scheduled__2023-03-27T01:40:00+00:00 [running]> on host vibrdairflow.tciw5gv3lhjetcyg0kqzfvdylc.hx.internal.cloudapp.net
[2023-03-29T04:37:31.355+0000] {taskinstance.py:1511} INFO - Exporting the following env vars:
AIRFLOW_CTX_DAG_EMAIL=airflow@example.com
AIRFLOW_CTX_DAG_OWNER=airflow
AIRFLOW_CTX_DAG_ID=docker_sample
AIRFLOW_CTX_TASK_ID=docker_op_tester
AIRFLOW_CTX_EXECUTION_DATE=2023-03-27T01:40:00+00:00
AIRFLOW_CTX_TRY_NUMBER=1
AIRFLOW_CTX_DAG_RUN_ID=scheduled__2023-03-27T01:40:00+00:00
[2023-03-29T04:37:31.378+0000] {taskinstance.py:1772} ERROR - Task failed with exception
Traceback (most recent call last):
  File "/home/azureuser/.local/lib/python3.8/site-packages/urllib3/connection.py", line 174, in _new_conn
    conn = connection.create_connection(
  File "/home/azureuser/.local/lib/python3.8/site-packages/urllib3/util/connection.py", line 72, in create_connection
    for res in socket.getaddrinfo(host, port, family, socket.SOCK_STREAM):
  File "/usr/lib/python3.8/socket.py", line 918, in getaddrinfo
    for res in _socket.getaddrinfo(host, port, family, type, proto, flags):
socket.gaierror: [Errno -3] Temporary failure in name resolution

During handling of the above exception, another exception occurred:

Traceback (most recent call last):
  File "/home/azureuser/.local/lib/python3.8/site-packages/urllib3/connectionpool.py", line 703, in urlopen
    httplib_response = self._make_request(
  File "/home/azureuser/.local/lib/python3.8/site-packages/urllib3/connectionpool.py", line 398, in _make_request
    conn.request(method, url, **httplib_request_kw)
  File "/home/azureuser/.local/lib/python3.8/site-packages/urllib3/connection.py", line 239, in request
    super(HTTPConnection, self).request(method, url, body=body, headers=headers)
  File "/usr/lib/python3.8/http/client.py", line 1256, in request
    self._send_request(method, url, body, headers, encode_chunked)
  File "/usr/lib/python3.8/http/client.py", line 1302, in _send_request
    self.endheaders(body, encode_chunked=encode_chunked)
  File "/usr/lib/python3.8/http/client.py", line 1251, in endheaders
    self._send_output(message_body, encode_chunked=encode_chunked)
  File "/usr/lib/python3.8/http/client.py", line 1011, in _send_output
    self.send(msg)
  File "/usr/lib/python3.8/http/client.py", line 951, in send
    self.connect()
  File "/home/azureuser/.local/lib/python3.8/site-packages/urllib3/connection.py", line 205, in connect
    conn = self._new_conn()
  File "/home/azureuser/.local/lib/python3.8/site-packages/urllib3/connection.py", line 186, in _new_conn
    raise NewConnectionError(
urllib3.exceptions.NewConnectionError: <urllib3.connection.HTTPConnection object at 0x7efe29ec27f0>: Failed to establish a new connection: [Errno -3] Temporary failure in name resolution

During handling of the above exception, another exception occurred:

Traceback (most recent call last):
  File "/home/azureuser/.local/lib/python3.8/site-packages/requests/adapters.py", line 489, in send
    resp = conn.urlopen(
  File "/home/azureuser/.local/lib/python3.8/site-packages/urllib3/connectionpool.py", line 787, in urlopen
    retries = retries.increment(
  File "/home/azureuser/.local/lib/python3.8/site-packages/urllib3/util/retry.py", line 592, in increment
    raise MaxRetryError(_pool, url, error or ResponseError(cause))
urllib3.exceptions.MaxRetryError: HTTPConnectionPool(host='docker-socket-proxy', port=2375): Max retries exceeded with url: /v1.30/images/json?only_ids=0&all=0&filters=%7B%22reference%22%3A+%5B%22centos%3Alatest%22%5D%7D (Caused by NewConnectionError('<urllib3.connection.HTTPConnection object at 0x7efe29ec27f0>: Failed to establish a new connection: [Errno -3] Temporary failure in name resolution'))

During handling of the above exception, another exception occurred:

Traceback (most recent call last):
  File "/home/azureuser/.local/lib/python3.8/site-packages/airflow/providers/docker/operators/docker.py", line 431, in execute
    if self.force_pull or not self.cli.images(name=self.image):
  File "/home/azureuser/.local/lib/python3.8/site-packages/docker/api/image.py", line 96, in images
    res = self._result(self._get(self._url("/images/json"), params=params),
  File "/home/azureuser/.local/lib/python3.8/site-packages/docker/utils/decorators.py", line 46, in inner
    return f(self, *args, **kwargs)
  File "/home/azureuser/.local/lib/python3.8/site-packages/docker/api/client.py", line 237, in _get
    return self.get(url, **self._set_request_timeout(kwargs))
  File "/home/azureuser/.local/lib/python3.8/site-packages/requests/sessions.py", line 600, in get
    return self.request("GET", url, **kwargs)
  File "/home/azureuser/.local/lib/python3.8/site-packages/requests/sessions.py", line 587, in request
    resp = self.send(prep, **send_kwargs)
  File "/home/azureuser/.local/lib/python3.8/site-packages/requests/sessions.py", line 701, in send
    r = adapter.send(request, **kwargs)
  File "/home/azureuser/.local/lib/python3.8/site-packages/requests/adapters.py", line 565, in send
    raise ConnectionError(e, request=request)
requests.exceptions.ConnectionError: HTTPConnectionPool(host='docker-socket-proxy', port=2375): Max retries exceeded with url: /v1.30/images/json?only_ids=0&all=0&filters=%7B%22reference%22%3A+%5B%22centos%3Alatest%22%5D%7D (Caused by NewConnectionError('<urllib3.connection.HTTPConnection object at 0x7efe29ec27f0>: Failed to establish a new connection: [Errno -3] Temporary failure in name resolution'))
[2023-03-29T04:37:31.388+0000] {taskinstance.py:1322} INFO - Marking task as UP_FOR_RETRY. dag_id=docker_sample, task_id=docker_op_tester, execution_date=20230327T014000, start_date=20230329T043731, end_date=20230329T043731
[2023-03-29T04:37:31.413+0000] {standard_task_runner.py:100} ERROR - Failed to execute job 121 for task docker_op_tester (HTTPConnectionPool(host='docker-socket-proxy', port=2375): Max retries exceeded with url: /v1.30/images/json?only_ids=0&all=0&filters=%7B%22reference%22%3A+%5B%22centos%3Alatest%22%5D%7D (Caused by NewConnectionError('<urllib3.connection.HTTPConnection object at 0x7efe29ec27f0>: Failed to establish a new connection: [Errno -3] Temporary failure in name resolution')); 180084)
[2023-03-29T04:37:31.430+0000] {local_task_job.py:159} INFO - Task exited with return code 1
[2023-03-29T04:37:31.449+0000] {taskinstance.py:2582} INFO - 0 downstream tasks scheduled from follow-on schedule check
