[2023-03-29T03:32:30.710+0000] {taskinstance.py:1087} INFO - Dependencies all met for <TaskInstance: dbt_kubernetes_pod.dbt_transformations manual__2023-03-29T03:27:23.683214+00:00 [queued]>
[2023-03-29T03:32:30.718+0000] {taskinstance.py:1087} INFO - Dependencies all met for <TaskInstance: dbt_kubernetes_pod.dbt_transformations manual__2023-03-29T03:27:23.683214+00:00 [queued]>
[2023-03-29T03:32:30.718+0000] {taskinstance.py:1283} INFO - 
--------------------------------------------------------------------------------
[2023-03-29T03:32:30.718+0000] {taskinstance.py:1284} INFO - Starting attempt 2 of 2
[2023-03-29T03:32:30.718+0000] {taskinstance.py:1285} INFO - 
--------------------------------------------------------------------------------
[2023-03-29T03:32:30.747+0000] {taskinstance.py:1304} INFO - Executing <Task(KubernetesPodOperator): dbt_transformations> on 2023-03-29 03:27:23.683214+00:00
[2023-03-29T03:32:30.750+0000] {standard_task_runner.py:55} INFO - Started process 99435 to run task
[2023-03-29T03:32:30.758+0000] {standard_task_runner.py:82} INFO - Running: ['airflow', 'tasks', 'run', 'dbt_kubernetes_pod', 'dbt_transformations', 'manual__2023-03-29T03:27:23.683214+00:00', '--job-id', '85', '--raw', '--subdir', 'DAGS_FOLDER/dbt-container-run.py', '--cfg-path', '/tmp/tmpknrzb70w']
[2023-03-29T03:32:30.760+0000] {standard_task_runner.py:83} INFO - Job 85: Subtask dbt_transformations
[2023-03-29T03:32:30.822+0000] {task_command.py:389} INFO - Running <TaskInstance: dbt_kubernetes_pod.dbt_transformations manual__2023-03-29T03:27:23.683214+00:00 [running]> on host vibrdairflow.tciw5gv3lhjetcyg0kqzfvdylc.hx.internal.cloudapp.net
[2023-03-29T03:32:30.896+0000] {taskinstance.py:1511} INFO - Exporting the following env vars:
AIRFLOW_CTX_DAG_OWNER=tan
AIRFLOW_CTX_DAG_ID=dbt_kubernetes_pod
AIRFLOW_CTX_TASK_ID=dbt_transformations
AIRFLOW_CTX_EXECUTION_DATE=2023-03-29T03:27:23.683214+00:00
AIRFLOW_CTX_TRY_NUMBER=2
AIRFLOW_CTX_DAG_RUN_ID=manual__2023-03-29T03:27:23.683214+00:00
[2023-03-29T03:32:30.903+0000] {kubernetes_pod.py:815} INFO - Building pod dbt-transformations-h7p9wizd with labels: {'dag_id': 'dbt_kubernetes_pod', 'task_id': 'dbt_transformations', 'run_id': 'manual__2023-03-29T032723.6832140000-92f7de070', 'kubernetes_pod_operator': 'True', 'try_number': '2'}
[2023-03-29T03:32:30.935+0000] {kubernetes_pod.py:870} ERROR - 'NoneType' object has no attribute 'metadata'
Traceback (most recent call last):
  File "/home/azureuser/.local/lib/python3.8/site-packages/airflow/providers/cncf/kubernetes/operators/kubernetes_pod.py", line 521, in execute_sync
    self.pod = self.get_or_create_pod(  # must set `self.pod` for `on_kill`
  File "/home/azureuser/.local/lib/python3.8/site-packages/airflow/providers/cncf/kubernetes/operators/kubernetes_pod.py", line 488, in get_or_create_pod
    self.pod_manager.create_pod(pod=pod_request_obj)
  File "/home/azureuser/.local/lib/python3.8/site-packages/tenacity/__init__.py", line 326, in wrapped_f
    return self(f, *args, **kw)
  File "/home/azureuser/.local/lib/python3.8/site-packages/tenacity/__init__.py", line 406, in __call__
    do = self.iter(retry_state=retry_state)
  File "/home/azureuser/.local/lib/python3.8/site-packages/tenacity/__init__.py", line 351, in iter
    return fut.result()
  File "/usr/lib/python3.8/concurrent/futures/_base.py", line 437, in result
    return self.__get_result()
  File "/usr/lib/python3.8/concurrent/futures/_base.py", line 389, in __get_result
    raise self._exception
  File "/home/azureuser/.local/lib/python3.8/site-packages/tenacity/__init__.py", line 409, in __call__
    result = fn(*args, **kwargs)
  File "/home/azureuser/.local/lib/python3.8/site-packages/airflow/providers/cncf/kubernetes/utils/pod_manager.py", line 171, in create_pod
    return self.run_pod_async(pod)
  File "/home/azureuser/.local/lib/python3.8/site-packages/airflow/providers/cncf/kubernetes/utils/pod_manager.py", line 136, in run_pod_async
    sanitized_pod = self._client.api_client.sanitize_for_serialization(pod)
  File "/home/azureuser/.local/lib/python3.8/site-packages/kubernetes/client/api_client.py", line 241, in sanitize_for_serialization
    return {key: self.sanitize_for_serialization(val)
  File "/home/azureuser/.local/lib/python3.8/site-packages/kubernetes/client/api_client.py", line 241, in <dictcomp>
    return {key: self.sanitize_for_serialization(val)
  File "/home/azureuser/.local/lib/python3.8/site-packages/kubernetes/client/api_client.py", line 241, in sanitize_for_serialization
    return {key: self.sanitize_for_serialization(val)
  File "/home/azureuser/.local/lib/python3.8/site-packages/kubernetes/client/api_client.py", line 241, in <dictcomp>
    return {key: self.sanitize_for_serialization(val)
  File "/home/azureuser/.local/lib/python3.8/site-packages/kubernetes/client/api_client.py", line 221, in sanitize_for_serialization
    return [self.sanitize_for_serialization(sub_obj)
  File "/home/azureuser/.local/lib/python3.8/site-packages/kubernetes/client/api_client.py", line 221, in <listcomp>
    return [self.sanitize_for_serialization(sub_obj)
  File "/home/azureuser/.local/lib/python3.8/site-packages/kubernetes/client/api_client.py", line 241, in sanitize_for_serialization
    return {key: self.sanitize_for_serialization(val)
  File "/home/azureuser/.local/lib/python3.8/site-packages/kubernetes/client/api_client.py", line 241, in <dictcomp>
    return {key: self.sanitize_for_serialization(val)
  File "/home/azureuser/.local/lib/python3.8/site-packages/kubernetes/client/api_client.py", line 241, in sanitize_for_serialization
    return {key: self.sanitize_for_serialization(val)
  File "/home/azureuser/.local/lib/python3.8/site-packages/kubernetes/client/api_client.py", line 241, in <dictcomp>
    return {key: self.sanitize_for_serialization(val)
  File "/home/azureuser/.local/lib/python3.8/site-packages/kubernetes/client/api_client.py", line 238, in sanitize_for_serialization
    for attr, _ in six.iteritems(obj.openapi_types)
AttributeError: 'set' object has no attribute 'openapi_types'

During handling of the above exception, another exception occurred:

Traceback (most recent call last):
  File "/home/azureuser/.local/lib/python3.8/site-packages/airflow/providers/cncf/kubernetes/operators/kubernetes_pod.py", line 713, in patch_already_checked
    name=pod.metadata.name,
AttributeError: 'NoneType' object has no attribute 'metadata'
[2023-03-29T03:32:30.942+0000] {taskinstance.py:1772} ERROR - Task failed with exception
Traceback (most recent call last):
  File "/home/azureuser/.local/lib/python3.8/site-packages/airflow/providers/cncf/kubernetes/operators/kubernetes_pod.py", line 521, in execute_sync
    self.pod = self.get_or_create_pod(  # must set `self.pod` for `on_kill`
  File "/home/azureuser/.local/lib/python3.8/site-packages/airflow/providers/cncf/kubernetes/operators/kubernetes_pod.py", line 488, in get_or_create_pod
    self.pod_manager.create_pod(pod=pod_request_obj)
  File "/home/azureuser/.local/lib/python3.8/site-packages/tenacity/__init__.py", line 326, in wrapped_f
    return self(f, *args, **kw)
  File "/home/azureuser/.local/lib/python3.8/site-packages/tenacity/__init__.py", line 406, in __call__
    do = self.iter(retry_state=retry_state)
  File "/home/azureuser/.local/lib/python3.8/site-packages/tenacity/__init__.py", line 351, in iter
    return fut.result()
  File "/usr/lib/python3.8/concurrent/futures/_base.py", line 437, in result
    return self.__get_result()
  File "/usr/lib/python3.8/concurrent/futures/_base.py", line 389, in __get_result
    raise self._exception
  File "/home/azureuser/.local/lib/python3.8/site-packages/tenacity/__init__.py", line 409, in __call__
    result = fn(*args, **kwargs)
  File "/home/azureuser/.local/lib/python3.8/site-packages/airflow/providers/cncf/kubernetes/utils/pod_manager.py", line 171, in create_pod
    return self.run_pod_async(pod)
  File "/home/azureuser/.local/lib/python3.8/site-packages/airflow/providers/cncf/kubernetes/utils/pod_manager.py", line 136, in run_pod_async
    sanitized_pod = self._client.api_client.sanitize_for_serialization(pod)
  File "/home/azureuser/.local/lib/python3.8/site-packages/kubernetes/client/api_client.py", line 241, in sanitize_for_serialization
    return {key: self.sanitize_for_serialization(val)
  File "/home/azureuser/.local/lib/python3.8/site-packages/kubernetes/client/api_client.py", line 241, in <dictcomp>
    return {key: self.sanitize_for_serialization(val)
  File "/home/azureuser/.local/lib/python3.8/site-packages/kubernetes/client/api_client.py", line 241, in sanitize_for_serialization
    return {key: self.sanitize_for_serialization(val)
  File "/home/azureuser/.local/lib/python3.8/site-packages/kubernetes/client/api_client.py", line 241, in <dictcomp>
    return {key: self.sanitize_for_serialization(val)
  File "/home/azureuser/.local/lib/python3.8/site-packages/kubernetes/client/api_client.py", line 221, in sanitize_for_serialization
    return [self.sanitize_for_serialization(sub_obj)
  File "/home/azureuser/.local/lib/python3.8/site-packages/kubernetes/client/api_client.py", line 221, in <listcomp>
    return [self.sanitize_for_serialization(sub_obj)
  File "/home/azureuser/.local/lib/python3.8/site-packages/kubernetes/client/api_client.py", line 241, in sanitize_for_serialization
    return {key: self.sanitize_for_serialization(val)
  File "/home/azureuser/.local/lib/python3.8/site-packages/kubernetes/client/api_client.py", line 241, in <dictcomp>
    return {key: self.sanitize_for_serialization(val)
  File "/home/azureuser/.local/lib/python3.8/site-packages/kubernetes/client/api_client.py", line 241, in sanitize_for_serialization
    return {key: self.sanitize_for_serialization(val)
  File "/home/azureuser/.local/lib/python3.8/site-packages/kubernetes/client/api_client.py", line 241, in <dictcomp>
    return {key: self.sanitize_for_serialization(val)
  File "/home/azureuser/.local/lib/python3.8/site-packages/kubernetes/client/api_client.py", line 238, in sanitize_for_serialization
    for attr, _ in six.iteritems(obj.openapi_types)
AttributeError: 'set' object has no attribute 'openapi_types'

During handling of the above exception, another exception occurred:

Traceback (most recent call last):
  File "/home/azureuser/.local/lib/python3.8/site-packages/airflow/providers/cncf/kubernetes/operators/kubernetes_pod.py", line 516, in execute
    return self.execute_sync(context)
  File "/home/azureuser/.local/lib/python3.8/site-packages/airflow/providers/cncf/kubernetes/operators/kubernetes_pod.py", line 545, in execute_sync
    self.cleanup(
  File "/home/azureuser/.local/lib/python3.8/site-packages/airflow/providers/cncf/kubernetes/operators/kubernetes_pod.py", line 671, in cleanup
    raise AirflowException(
airflow.exceptions.AirflowException: Pod dbt-transformations-h7p9wizd returned a failure:

remote_pod: None
[2023-03-29T03:32:30.944+0000] {taskinstance.py:1322} INFO - Marking task as FAILED. dag_id=dbt_kubernetes_pod, task_id=dbt_transformations, execution_date=20230329T032723, start_date=20230329T033230, end_date=20230329T033230
[2023-03-29T03:32:30.968+0000] {standard_task_runner.py:100} ERROR - Failed to execute job 85 for task dbt_transformations (Pod dbt-transformations-h7p9wizd returned a failure:

remote_pod: None; 99435)
[2023-03-29T03:32:31.006+0000] {local_task_job.py:159} INFO - Task exited with return code 1
[2023-03-29T03:32:31.020+0000] {taskinstance.py:2582} INFO - 0 downstream tasks scheduled from follow-on schedule check
